0401_15:19:18 Traceback (most recent call last):
  File "E:\restapi-teach\backend\services\datamodel\common\models.py", line 205, in add
    courseidList = [one['id'] for one in  data['courses']]
  File "E:\restapi-teach\backend\services\datamodel\common\models.py", line 205, in <listcomp>
    courseidList = [one['id'] for one in  data['courses']]
TypeError: string indices must be integers

0401_16:54:51 Traceback (most recent call last):
  File "E:\restapi-teach\backend\services\datamodel\common\models.py", line 205, in add
    courseidList = [one['id'] for one in  data['courses']]
  File "E:\restapi-teach\backend\services\datamodel\common\models.py", line 205, in <listcomp>
    courseidList = [one['id'] for one in  data['courses']]
TypeError: string indices must be integers

0922_19:25:00 Traceback (most recent call last):
  File "D:\Program Files\Python36\lib\site-packages\django\db\backends\utils.py", line 85, in _execute
    return self.cursor.execute(sql, params)
  File "D:\Program Files\Python36\lib\site-packages\django\db\backends\sqlite3\base.py", line 303, in execute
    return Database.Cursor.execute(self, query, params)
sqlite3.IntegrityError: FOREIGN KEY constraint failed

The above exception was the direct cause of the following exception:

Traceback (most recent call last):
  File "C:\Users\Think\Desktop\入口\自动化测试\restapi-teach\backend\services\datamodel\common\models.py", line 206, in add
    teacher.courses.add(*courseidList)
  File "D:\Program Files\Python36\lib\site-packages\django\db\models\fields\related_descriptors.py", line 898, in add
    self._add_items(self.source_field_name, self.target_field_name, *objs)
  File "D:\Program Files\Python36\lib\site-packages\django\db\models\fields\related_descriptors.py", line 1065, in _add_items
    for obj_id in new_ids
  File "D:\Program Files\Python36\lib\site-packages\django\db\models\query.py", line 466, in bulk_create
    ids = self._batched_insert(objs_without_pk, fields, batch_size)
  File "D:\Program Files\Python36\lib\site-packages\django\db\models\query.py", line 1148, in _batched_insert
    self._insert(item, fields=fields, using=self.db)
  File "D:\Program Files\Python36\lib\site-packages\django\db\models\query.py", line 1125, in _insert
    return query.get_compiler(using=using).execute_sql(return_id)
  File "D:\Program Files\Python36\lib\site-packages\django\db\models\sql\compiler.py", line 1284, in execute_sql
    cursor.execute(sql, params)
  File "D:\Program Files\Python36\lib\site-packages\django\db\backends\utils.py", line 100, in execute
    return super().execute(sql, params)
  File "D:\Program Files\Python36\lib\site-packages\django\db\backends\utils.py", line 68, in execute
    return self._execute_with_wrappers(sql, params, many=False, executor=self._execute)
  File "D:\Program Files\Python36\lib\site-packages\django\db\backends\utils.py", line 77, in _execute_with_wrappers
    return executor(sql, params, many, context)
  File "D:\Program Files\Python36\lib\site-packages\django\db\backends\utils.py", line 85, in _execute
    return self.cursor.execute(sql, params)
  File "D:\Program Files\Python36\lib\site-packages\django\db\utils.py", line 89, in __exit__
    raise dj_exc_value.with_traceback(traceback) from exc_value
  File "D:\Program Files\Python36\lib\site-packages\django\db\backends\utils.py", line 85, in _execute
    return self.cursor.execute(sql, params)
  File "D:\Program Files\Python36\lib\site-packages\django\db\backends\sqlite3\base.py", line 303, in execute
    return Database.Cursor.execute(self, query, params)
django.db.utils.IntegrityError: FOREIGN KEY constraint failed

0922_19:25:48 Traceback (most recent call last):
  File "D:\Program Files\Python36\lib\site-packages\django\db\backends\utils.py", line 85, in _execute
    return self.cursor.execute(sql, params)
  File "D:\Program Files\Python36\lib\site-packages\django\db\backends\sqlite3\base.py", line 303, in execute
    return Database.Cursor.execute(self, query, params)
sqlite3.IntegrityError: FOREIGN KEY constraint failed

The above exception was the direct cause of the following exception:

Traceback (most recent call last):
  File "C:\Users\Think\Desktop\入口\自动化测试\restapi-teach\backend\services\datamodel\common\models.py", line 206, in add
    teacher.courses.add(*courseidList)
  File "D:\Program Files\Python36\lib\site-packages\django\db\models\fields\related_descriptors.py", line 898, in add
    self._add_items(self.source_field_name, self.target_field_name, *objs)
  File "D:\Program Files\Python36\lib\site-packages\django\db\models\fields\related_descriptors.py", line 1065, in _add_items
    for obj_id in new_ids
  File "D:\Program Files\Python36\lib\site-packages\django\db\models\query.py", line 466, in bulk_create
    ids = self._batched_insert(objs_without_pk, fields, batch_size)
  File "D:\Program Files\Python36\lib\site-packages\django\db\models\query.py", line 1148, in _batched_insert
    self._insert(item, fields=fields, using=self.db)
  File "D:\Program Files\Python36\lib\site-packages\django\db\models\query.py", line 1125, in _insert
    return query.get_compiler(using=using).execute_sql(return_id)
  File "D:\Program Files\Python36\lib\site-packages\django\db\models\sql\compiler.py", line 1284, in execute_sql
    cursor.execute(sql, params)
  File "D:\Program Files\Python36\lib\site-packages\django\db\backends\utils.py", line 100, in execute
    return super().execute(sql, params)
  File "D:\Program Files\Python36\lib\site-packages\django\db\backends\utils.py", line 68, in execute
    return self._execute_with_wrappers(sql, params, many=False, executor=self._execute)
  File "D:\Program Files\Python36\lib\site-packages\django\db\backends\utils.py", line 77, in _execute_with_wrappers
    return executor(sql, params, many, context)
  File "D:\Program Files\Python36\lib\site-packages\django\db\backends\utils.py", line 85, in _execute
    return self.cursor.execute(sql, params)
  File "D:\Program Files\Python36\lib\site-packages\django\db\utils.py", line 89, in __exit__
    raise dj_exc_value.with_traceback(traceback) from exc_value
  File "D:\Program Files\Python36\lib\site-packages\django\db\backends\utils.py", line 85, in _execute
    return self.cursor.execute(sql, params)
  File "D:\Program Files\Python36\lib\site-packages\django\db\backends\sqlite3\base.py", line 303, in execute
    return Database.Cursor.execute(self, query, params)
django.db.utils.IntegrityError: FOREIGN KEY constraint failed

0922_19:26:25 Traceback (most recent call last):
  File "D:\Program Files\Python36\lib\site-packages\django\db\backends\utils.py", line 85, in _execute
    return self.cursor.execute(sql, params)
  File "D:\Program Files\Python36\lib\site-packages\django\db\backends\sqlite3\base.py", line 303, in execute
    return Database.Cursor.execute(self, query, params)
sqlite3.IntegrityError: FOREIGN KEY constraint failed

The above exception was the direct cause of the following exception:

Traceback (most recent call last):
  File "C:\Users\Think\Desktop\入口\自动化测试\restapi-teach\backend\services\datamodel\common\models.py", line 206, in add
    teacher.courses.add(*courseidList)
  File "D:\Program Files\Python36\lib\site-packages\django\db\models\fields\related_descriptors.py", line 898, in add
    self._add_items(self.source_field_name, self.target_field_name, *objs)
  File "D:\Program Files\Python36\lib\site-packages\django\db\models\fields\related_descriptors.py", line 1065, in _add_items
    for obj_id in new_ids
  File "D:\Program Files\Python36\lib\site-packages\django\db\models\query.py", line 466, in bulk_create
    ids = self._batched_insert(objs_without_pk, fields, batch_size)
  File "D:\Program Files\Python36\lib\site-packages\django\db\models\query.py", line 1148, in _batched_insert
    self._insert(item, fields=fields, using=self.db)
  File "D:\Program Files\Python36\lib\site-packages\django\db\models\query.py", line 1125, in _insert
    return query.get_compiler(using=using).execute_sql(return_id)
  File "D:\Program Files\Python36\lib\site-packages\django\db\models\sql\compiler.py", line 1284, in execute_sql
    cursor.execute(sql, params)
  File "D:\Program Files\Python36\lib\site-packages\django\db\backends\utils.py", line 100, in execute
    return super().execute(sql, params)
  File "D:\Program Files\Python36\lib\site-packages\django\db\backends\utils.py", line 68, in execute
    return self._execute_with_wrappers(sql, params, many=False, executor=self._execute)
  File "D:\Program Files\Python36\lib\site-packages\django\db\backends\utils.py", line 77, in _execute_with_wrappers
    return executor(sql, params, many, context)
  File "D:\Program Files\Python36\lib\site-packages\django\db\backends\utils.py", line 85, in _execute
    return self.cursor.execute(sql, params)
  File "D:\Program Files\Python36\lib\site-packages\django\db\utils.py", line 89, in __exit__
    raise dj_exc_value.with_traceback(traceback) from exc_value
  File "D:\Program Files\Python36\lib\site-packages\django\db\backends\utils.py", line 85, in _execute
    return self.cursor.execute(sql, params)
  File "D:\Program Files\Python36\lib\site-packages\django\db\backends\sqlite3\base.py", line 303, in execute
    return Database.Cursor.execute(self, query, params)
django.db.utils.IntegrityError: FOREIGN KEY constraint failed

0922_19:26:49 Traceback (most recent call last):
  File "D:\Program Files\Python36\lib\site-packages\django\db\backends\utils.py", line 85, in _execute
    return self.cursor.execute(sql, params)
  File "D:\Program Files\Python36\lib\site-packages\django\db\backends\sqlite3\base.py", line 303, in execute
    return Database.Cursor.execute(self, query, params)
sqlite3.IntegrityError: FOREIGN KEY constraint failed

The above exception was the direct cause of the following exception:

Traceback (most recent call last):
  File "C:\Users\Think\Desktop\入口\自动化测试\restapi-teach\backend\services\datamodel\common\models.py", line 206, in add
    teacher.courses.add(*courseidList)
  File "D:\Program Files\Python36\lib\site-packages\django\db\models\fields\related_descriptors.py", line 898, in add
    self._add_items(self.source_field_name, self.target_field_name, *objs)
  File "D:\Program Files\Python36\lib\site-packages\django\db\models\fields\related_descriptors.py", line 1065, in _add_items
    for obj_id in new_ids
  File "D:\Program Files\Python36\lib\site-packages\django\db\models\query.py", line 466, in bulk_create
    ids = self._batched_insert(objs_without_pk, fields, batch_size)
  File "D:\Program Files\Python36\lib\site-packages\django\db\models\query.py", line 1148, in _batched_insert
    self._insert(item, fields=fields, using=self.db)
  File "D:\Program Files\Python36\lib\site-packages\django\db\models\query.py", line 1125, in _insert
    return query.get_compiler(using=using).execute_sql(return_id)
  File "D:\Program Files\Python36\lib\site-packages\django\db\models\sql\compiler.py", line 1284, in execute_sql
    cursor.execute(sql, params)
  File "D:\Program Files\Python36\lib\site-packages\django\db\backends\utils.py", line 100, in execute
    return super().execute(sql, params)
  File "D:\Program Files\Python36\lib\site-packages\django\db\backends\utils.py", line 68, in execute
    return self._execute_with_wrappers(sql, params, many=False, executor=self._execute)
  File "D:\Program Files\Python36\lib\site-packages\django\db\backends\utils.py", line 77, in _execute_with_wrappers
    return executor(sql, params, many, context)
  File "D:\Program Files\Python36\lib\site-packages\django\db\backends\utils.py", line 85, in _execute
    return self.cursor.execute(sql, params)
  File "D:\Program Files\Python36\lib\site-packages\django\db\utils.py", line 89, in __exit__
    raise dj_exc_value.with_traceback(traceback) from exc_value
  File "D:\Program Files\Python36\lib\site-packages\django\db\backends\utils.py", line 85, in _execute
    return self.cursor.execute(sql, params)
  File "D:\Program Files\Python36\lib\site-packages\django\db\backends\sqlite3\base.py", line 303, in execute
    return Database.Cursor.execute(self, query, params)
django.db.utils.IntegrityError: FOREIGN KEY constraint failed

0922_19:27:04 Traceback (most recent call last):
  File "D:\Program Files\Python36\lib\site-packages\django\db\backends\utils.py", line 85, in _execute
    return self.cursor.execute(sql, params)
  File "D:\Program Files\Python36\lib\site-packages\django\db\backends\sqlite3\base.py", line 303, in execute
    return Database.Cursor.execute(self, query, params)
sqlite3.IntegrityError: FOREIGN KEY constraint failed

The above exception was the direct cause of the following exception:

Traceback (most recent call last):
  File "C:\Users\Think\Desktop\入口\自动化测试\restapi-teach\backend\services\datamodel\common\models.py", line 206, in add
    teacher.courses.add(*courseidList)
  File "D:\Program Files\Python36\lib\site-packages\django\db\models\fields\related_descriptors.py", line 898, in add
    self._add_items(self.source_field_name, self.target_field_name, *objs)
  File "D:\Program Files\Python36\lib\site-packages\django\db\models\fields\related_descriptors.py", line 1065, in _add_items
    for obj_id in new_ids
  File "D:\Program Files\Python36\lib\site-packages\django\db\models\query.py", line 466, in bulk_create
    ids = self._batched_insert(objs_without_pk, fields, batch_size)
  File "D:\Program Files\Python36\lib\site-packages\django\db\models\query.py", line 1148, in _batched_insert
    self._insert(item, fields=fields, using=self.db)
  File "D:\Program Files\Python36\lib\site-packages\django\db\models\query.py", line 1125, in _insert
    return query.get_compiler(using=using).execute_sql(return_id)
  File "D:\Program Files\Python36\lib\site-packages\django\db\models\sql\compiler.py", line 1284, in execute_sql
    cursor.execute(sql, params)
  File "D:\Program Files\Python36\lib\site-packages\django\db\backends\utils.py", line 100, in execute
    return super().execute(sql, params)
  File "D:\Program Files\Python36\lib\site-packages\django\db\backends\utils.py", line 68, in execute
    return self._execute_with_wrappers(sql, params, many=False, executor=self._execute)
  File "D:\Program Files\Python36\lib\site-packages\django\db\backends\utils.py", line 77, in _execute_with_wrappers
    return executor(sql, params, many, context)
  File "D:\Program Files\Python36\lib\site-packages\django\db\backends\utils.py", line 85, in _execute
    return self.cursor.execute(sql, params)
  File "D:\Program Files\Python36\lib\site-packages\django\db\utils.py", line 89, in __exit__
    raise dj_exc_value.with_traceback(traceback) from exc_value
  File "D:\Program Files\Python36\lib\site-packages\django\db\backends\utils.py", line 85, in _execute
    return self.cursor.execute(sql, params)
  File "D:\Program Files\Python36\lib\site-packages\django\db\backends\sqlite3\base.py", line 303, in execute
    return Database.Cursor.execute(self, query, params)
django.db.utils.IntegrityError: FOREIGN KEY constraint failed

0922_19:27:44 Traceback (most recent call last):
  File "D:\Program Files\Python36\lib\site-packages\django\db\backends\utils.py", line 85, in _execute
    return self.cursor.execute(sql, params)
  File "D:\Program Files\Python36\lib\site-packages\django\db\backends\sqlite3\base.py", line 303, in execute
    return Database.Cursor.execute(self, query, params)
sqlite3.IntegrityError: FOREIGN KEY constraint failed

The above exception was the direct cause of the following exception:

Traceback (most recent call last):
  File "C:\Users\Think\Desktop\入口\自动化测试\restapi-teach\backend\services\datamodel\common\models.py", line 206, in add
    teacher.courses.add(*courseidList)
  File "D:\Program Files\Python36\lib\site-packages\django\db\models\fields\related_descriptors.py", line 898, in add
    self._add_items(self.source_field_name, self.target_field_name, *objs)
  File "D:\Program Files\Python36\lib\site-packages\django\db\models\fields\related_descriptors.py", line 1065, in _add_items
    for obj_id in new_ids
  File "D:\Program Files\Python36\lib\site-packages\django\db\models\query.py", line 466, in bulk_create
    ids = self._batched_insert(objs_without_pk, fields, batch_size)
  File "D:\Program Files\Python36\lib\site-packages\django\db\models\query.py", line 1148, in _batched_insert
    self._insert(item, fields=fields, using=self.db)
  File "D:\Program Files\Python36\lib\site-packages\django\db\models\query.py", line 1125, in _insert
    return query.get_compiler(using=using).execute_sql(return_id)
  File "D:\Program Files\Python36\lib\site-packages\django\db\models\sql\compiler.py", line 1284, in execute_sql
    cursor.execute(sql, params)
  File "D:\Program Files\Python36\lib\site-packages\django\db\backends\utils.py", line 100, in execute
    return super().execute(sql, params)
  File "D:\Program Files\Python36\lib\site-packages\django\db\backends\utils.py", line 68, in execute
    return self._execute_with_wrappers(sql, params, many=False, executor=self._execute)
  File "D:\Program Files\Python36\lib\site-packages\django\db\backends\utils.py", line 77, in _execute_with_wrappers
    return executor(sql, params, many, context)
  File "D:\Program Files\Python36\lib\site-packages\django\db\backends\utils.py", line 85, in _execute
    return self.cursor.execute(sql, params)
  File "D:\Program Files\Python36\lib\site-packages\django\db\utils.py", line 89, in __exit__
    raise dj_exc_value.with_traceback(traceback) from exc_value
  File "D:\Program Files\Python36\lib\site-packages\django\db\backends\utils.py", line 85, in _execute
    return self.cursor.execute(sql, params)
  File "D:\Program Files\Python36\lib\site-packages\django\db\backends\sqlite3\base.py", line 303, in execute
    return Database.Cursor.execute(self, query, params)
django.db.utils.IntegrityError: FOREIGN KEY constraint failed

0922_19:33:28 Traceback (most recent call last):
  File "D:\Program Files\Python36\lib\site-packages\django\db\backends\utils.py", line 85, in _execute
    return self.cursor.execute(sql, params)
  File "D:\Program Files\Python36\lib\site-packages\django\db\backends\sqlite3\base.py", line 303, in execute
    return Database.Cursor.execute(self, query, params)
sqlite3.IntegrityError: FOREIGN KEY constraint failed

The above exception was the direct cause of the following exception:

Traceback (most recent call last):
  File "C:\Users\Think\Desktop\入口\自动化测试\restapi-teach\backend\services\datamodel\common\models.py", line 206, in add
    teacher.courses.add(*courseidList)
  File "D:\Program Files\Python36\lib\site-packages\django\db\models\fields\related_descriptors.py", line 898, in add
    self._add_items(self.source_field_name, self.target_field_name, *objs)
  File "D:\Program Files\Python36\lib\site-packages\django\db\models\fields\related_descriptors.py", line 1065, in _add_items
    for obj_id in new_ids
  File "D:\Program Files\Python36\lib\site-packages\django\db\models\query.py", line 466, in bulk_create
    ids = self._batched_insert(objs_without_pk, fields, batch_size)
  File "D:\Program Files\Python36\lib\site-packages\django\db\models\query.py", line 1148, in _batched_insert
    self._insert(item, fields=fields, using=self.db)
  File "D:\Program Files\Python36\lib\site-packages\django\db\models\query.py", line 1125, in _insert
    return query.get_compiler(using=using).execute_sql(return_id)
  File "D:\Program Files\Python36\lib\site-packages\django\db\models\sql\compiler.py", line 1284, in execute_sql
    cursor.execute(sql, params)
  File "D:\Program Files\Python36\lib\site-packages\django\db\backends\utils.py", line 100, in execute
    return super().execute(sql, params)
  File "D:\Program Files\Python36\lib\site-packages\django\db\backends\utils.py", line 68, in execute
    return self._execute_with_wrappers(sql, params, many=False, executor=self._execute)
  File "D:\Program Files\Python36\lib\site-packages\django\db\backends\utils.py", line 77, in _execute_with_wrappers
    return executor(sql, params, many, context)
  File "D:\Program Files\Python36\lib\site-packages\django\db\backends\utils.py", line 85, in _execute
    return self.cursor.execute(sql, params)
  File "D:\Program Files\Python36\lib\site-packages\django\db\utils.py", line 89, in __exit__
    raise dj_exc_value.with_traceback(traceback) from exc_value
  File "D:\Program Files\Python36\lib\site-packages\django\db\backends\utils.py", line 85, in _execute
    return self.cursor.execute(sql, params)
  File "D:\Program Files\Python36\lib\site-packages\django\db\backends\sqlite3\base.py", line 303, in execute
    return Database.Cursor.execute(self, query, params)
django.db.utils.IntegrityError: FOREIGN KEY constraint failed

0922_19:34:10 Traceback (most recent call last):
  File "D:\Program Files\Python36\lib\site-packages\django\db\backends\utils.py", line 85, in _execute
    return self.cursor.execute(sql, params)
  File "D:\Program Files\Python36\lib\site-packages\django\db\backends\sqlite3\base.py", line 303, in execute
    return Database.Cursor.execute(self, query, params)
sqlite3.IntegrityError: FOREIGN KEY constraint failed

The above exception was the direct cause of the following exception:

Traceback (most recent call last):
  File "C:\Users\Think\Desktop\入口\自动化测试\restapi-teach\backend\services\datamodel\common\models.py", line 206, in add
    teacher.courses.add(*courseidList)
  File "D:\Program Files\Python36\lib\site-packages\django\db\models\fields\related_descriptors.py", line 898, in add
    self._add_items(self.source_field_name, self.target_field_name, *objs)
  File "D:\Program Files\Python36\lib\site-packages\django\db\models\fields\related_descriptors.py", line 1065, in _add_items
    for obj_id in new_ids
  File "D:\Program Files\Python36\lib\site-packages\django\db\models\query.py", line 466, in bulk_create
    ids = self._batched_insert(objs_without_pk, fields, batch_size)
  File "D:\Program Files\Python36\lib\site-packages\django\db\models\query.py", line 1148, in _batched_insert
    self._insert(item, fields=fields, using=self.db)
  File "D:\Program Files\Python36\lib\site-packages\django\db\models\query.py", line 1125, in _insert
    return query.get_compiler(using=using).execute_sql(return_id)
  File "D:\Program Files\Python36\lib\site-packages\django\db\models\sql\compiler.py", line 1284, in execute_sql
    cursor.execute(sql, params)
  File "D:\Program Files\Python36\lib\site-packages\django\db\backends\utils.py", line 100, in execute
    return super().execute(sql, params)
  File "D:\Program Files\Python36\lib\site-packages\django\db\backends\utils.py", line 68, in execute
    return self._execute_with_wrappers(sql, params, many=False, executor=self._execute)
  File "D:\Program Files\Python36\lib\site-packages\django\db\backends\utils.py", line 77, in _execute_with_wrappers
    return executor(sql, params, many, context)
  File "D:\Program Files\Python36\lib\site-packages\django\db\backends\utils.py", line 85, in _execute
    return self.cursor.execute(sql, params)
  File "D:\Program Files\Python36\lib\site-packages\django\db\utils.py", line 89, in __exit__
    raise dj_exc_value.with_traceback(traceback) from exc_value
  File "D:\Program Files\Python36\lib\site-packages\django\db\backends\utils.py", line 85, in _execute
    return self.cursor.execute(sql, params)
  File "D:\Program Files\Python36\lib\site-packages\django\db\backends\sqlite3\base.py", line 303, in execute
    return Database.Cursor.execute(self, query, params)
django.db.utils.IntegrityError: FOREIGN KEY constraint failed

0922_19:38:04 Traceback (most recent call last):
  File "D:\Program Files\Python36\lib\site-packages\django\db\backends\utils.py", line 85, in _execute
    return self.cursor.execute(sql, params)
  File "D:\Program Files\Python36\lib\site-packages\django\db\backends\sqlite3\base.py", line 303, in execute
    return Database.Cursor.execute(self, query, params)
sqlite3.IntegrityError: FOREIGN KEY constraint failed

The above exception was the direct cause of the following exception:

Traceback (most recent call last):
  File "C:\Users\Think\Desktop\入口\自动化测试\restapi-teach\backend\services\datamodel\common\models.py", line 206, in add
    teacher.courses.add(*courseidList)
  File "D:\Program Files\Python36\lib\site-packages\django\db\models\fields\related_descriptors.py", line 898, in add
    self._add_items(self.source_field_name, self.target_field_name, *objs)
  File "D:\Program Files\Python36\lib\site-packages\django\db\models\fields\related_descriptors.py", line 1065, in _add_items
    for obj_id in new_ids
  File "D:\Program Files\Python36\lib\site-packages\django\db\models\query.py", line 466, in bulk_create
    ids = self._batched_insert(objs_without_pk, fields, batch_size)
  File "D:\Program Files\Python36\lib\site-packages\django\db\models\query.py", line 1148, in _batched_insert
    self._insert(item, fields=fields, using=self.db)
  File "D:\Program Files\Python36\lib\site-packages\django\db\models\query.py", line 1125, in _insert
    return query.get_compiler(using=using).execute_sql(return_id)
  File "D:\Program Files\Python36\lib\site-packages\django\db\models\sql\compiler.py", line 1284, in execute_sql
    cursor.execute(sql, params)
  File "D:\Program Files\Python36\lib\site-packages\django\db\backends\utils.py", line 100, in execute
    return super().execute(sql, params)
  File "D:\Program Files\Python36\lib\site-packages\django\db\backends\utils.py", line 68, in execute
    return self._execute_with_wrappers(sql, params, many=False, executor=self._execute)
  File "D:\Program Files\Python36\lib\site-packages\django\db\backends\utils.py", line 77, in _execute_with_wrappers
    return executor(sql, params, many, context)
  File "D:\Program Files\Python36\lib\site-packages\django\db\backends\utils.py", line 85, in _execute
    return self.cursor.execute(sql, params)
  File "D:\Program Files\Python36\lib\site-packages\django\db\utils.py", line 89, in __exit__
    raise dj_exc_value.with_traceback(traceback) from exc_value
  File "D:\Program Files\Python36\lib\site-packages\django\db\backends\utils.py", line 85, in _execute
    return self.cursor.execute(sql, params)
  File "D:\Program Files\Python36\lib\site-packages\django\db\backends\sqlite3\base.py", line 303, in execute
    return Database.Cursor.execute(self, query, params)
django.db.utils.IntegrityError: FOREIGN KEY constraint failed

0922_19:39:37 Traceback (most recent call last):
  File "D:\Program Files\Python36\lib\site-packages\django\db\backends\utils.py", line 85, in _execute
    return self.cursor.execute(sql, params)
  File "D:\Program Files\Python36\lib\site-packages\django\db\backends\sqlite3\base.py", line 303, in execute
    return Database.Cursor.execute(self, query, params)
sqlite3.IntegrityError: FOREIGN KEY constraint failed

The above exception was the direct cause of the following exception:

Traceback (most recent call last):
  File "C:\Users\Think\Desktop\入口\自动化测试\restapi-teach\backend\services\datamodel\common\models.py", line 206, in add
    teacher.courses.add(*courseidList)
  File "D:\Program Files\Python36\lib\site-packages\django\db\models\fields\related_descriptors.py", line 898, in add
    self._add_items(self.source_field_name, self.target_field_name, *objs)
  File "D:\Program Files\Python36\lib\site-packages\django\db\models\fields\related_descriptors.py", line 1065, in _add_items
    for obj_id in new_ids
  File "D:\Program Files\Python36\lib\site-packages\django\db\models\query.py", line 466, in bulk_create
    ids = self._batched_insert(objs_without_pk, fields, batch_size)
  File "D:\Program Files\Python36\lib\site-packages\django\db\models\query.py", line 1148, in _batched_insert
    self._insert(item, fields=fields, using=self.db)
  File "D:\Program Files\Python36\lib\site-packages\django\db\models\query.py", line 1125, in _insert
    return query.get_compiler(using=using).execute_sql(return_id)
  File "D:\Program Files\Python36\lib\site-packages\django\db\models\sql\compiler.py", line 1284, in execute_sql
    cursor.execute(sql, params)
  File "D:\Program Files\Python36\lib\site-packages\django\db\backends\utils.py", line 100, in execute
    return super().execute(sql, params)
  File "D:\Program Files\Python36\lib\site-packages\django\db\backends\utils.py", line 68, in execute
    return self._execute_with_wrappers(sql, params, many=False, executor=self._execute)
  File "D:\Program Files\Python36\lib\site-packages\django\db\backends\utils.py", line 77, in _execute_with_wrappers
    return executor(sql, params, many, context)
  File "D:\Program Files\Python36\lib\site-packages\django\db\backends\utils.py", line 85, in _execute
    return self.cursor.execute(sql, params)
  File "D:\Program Files\Python36\lib\site-packages\django\db\utils.py", line 89, in __exit__
    raise dj_exc_value.with_traceback(traceback) from exc_value
  File "D:\Program Files\Python36\lib\site-packages\django\db\backends\utils.py", line 85, in _execute
    return self.cursor.execute(sql, params)
  File "D:\Program Files\Python36\lib\site-packages\django\db\backends\sqlite3\base.py", line 303, in execute
    return Database.Cursor.execute(self, query, params)
django.db.utils.IntegrityError: FOREIGN KEY constraint failed

0922_19:39:56 Traceback (most recent call last):
  File "D:\Program Files\Python36\lib\site-packages\django\db\backends\utils.py", line 85, in _execute
    return self.cursor.execute(sql, params)
  File "D:\Program Files\Python36\lib\site-packages\django\db\backends\sqlite3\base.py", line 303, in execute
    return Database.Cursor.execute(self, query, params)
sqlite3.IntegrityError: FOREIGN KEY constraint failed

The above exception was the direct cause of the following exception:

Traceback (most recent call last):
  File "C:\Users\Think\Desktop\入口\自动化测试\restapi-teach\backend\services\datamodel\common\models.py", line 206, in add
    teacher.courses.add(*courseidList)
  File "D:\Program Files\Python36\lib\site-packages\django\db\models\fields\related_descriptors.py", line 898, in add
    self._add_items(self.source_field_name, self.target_field_name, *objs)
  File "D:\Program Files\Python36\lib\site-packages\django\db\models\fields\related_descriptors.py", line 1065, in _add_items
    for obj_id in new_ids
  File "D:\Program Files\Python36\lib\site-packages\django\db\models\query.py", line 466, in bulk_create
    ids = self._batched_insert(objs_without_pk, fields, batch_size)
  File "D:\Program Files\Python36\lib\site-packages\django\db\models\query.py", line 1148, in _batched_insert
    self._insert(item, fields=fields, using=self.db)
  File "D:\Program Files\Python36\lib\site-packages\django\db\models\query.py", line 1125, in _insert
    return query.get_compiler(using=using).execute_sql(return_id)
  File "D:\Program Files\Python36\lib\site-packages\django\db\models\sql\compiler.py", line 1284, in execute_sql
    cursor.execute(sql, params)
  File "D:\Program Files\Python36\lib\site-packages\django\db\backends\utils.py", line 100, in execute
    return super().execute(sql, params)
  File "D:\Program Files\Python36\lib\site-packages\django\db\backends\utils.py", line 68, in execute
    return self._execute_with_wrappers(sql, params, many=False, executor=self._execute)
  File "D:\Program Files\Python36\lib\site-packages\django\db\backends\utils.py", line 77, in _execute_with_wrappers
    return executor(sql, params, many, context)
  File "D:\Program Files\Python36\lib\site-packages\django\db\backends\utils.py", line 85, in _execute
    return self.cursor.execute(sql, params)
  File "D:\Program Files\Python36\lib\site-packages\django\db\utils.py", line 89, in __exit__
    raise dj_exc_value.with_traceback(traceback) from exc_value
  File "D:\Program Files\Python36\lib\site-packages\django\db\backends\utils.py", line 85, in _execute
    return self.cursor.execute(sql, params)
  File "D:\Program Files\Python36\lib\site-packages\django\db\backends\sqlite3\base.py", line 303, in execute
    return Database.Cursor.execute(self, query, params)
django.db.utils.IntegrityError: FOREIGN KEY constraint failed

0922_19:43:41 Traceback (most recent call last):
  File "D:\Program Files\Python36\lib\site-packages\django\db\backends\utils.py", line 85, in _execute
    return self.cursor.execute(sql, params)
  File "D:\Program Files\Python36\lib\site-packages\django\db\backends\sqlite3\base.py", line 303, in execute
    return Database.Cursor.execute(self, query, params)
sqlite3.IntegrityError: FOREIGN KEY constraint failed

The above exception was the direct cause of the following exception:

Traceback (most recent call last):
  File "C:\Users\Think\Desktop\入口\自动化测试\restapi-teach\backend\services\datamodel\common\models.py", line 206, in add
    teacher.courses.add(*courseidList)
  File "D:\Program Files\Python36\lib\site-packages\django\db\models\fields\related_descriptors.py", line 898, in add
    self._add_items(self.source_field_name, self.target_field_name, *objs)
  File "D:\Program Files\Python36\lib\site-packages\django\db\models\fields\related_descriptors.py", line 1065, in _add_items
    for obj_id in new_ids
  File "D:\Program Files\Python36\lib\site-packages\django\db\models\query.py", line 466, in bulk_create
    ids = self._batched_insert(objs_without_pk, fields, batch_size)
  File "D:\Program Files\Python36\lib\site-packages\django\db\models\query.py", line 1148, in _batched_insert
    self._insert(item, fields=fields, using=self.db)
  File "D:\Program Files\Python36\lib\site-packages\django\db\models\query.py", line 1125, in _insert
    return query.get_compiler(using=using).execute_sql(return_id)
  File "D:\Program Files\Python36\lib\site-packages\django\db\models\sql\compiler.py", line 1284, in execute_sql
    cursor.execute(sql, params)
  File "D:\Program Files\Python36\lib\site-packages\django\db\backends\utils.py", line 100, in execute
    return super().execute(sql, params)
  File "D:\Program Files\Python36\lib\site-packages\django\db\backends\utils.py", line 68, in execute
    return self._execute_with_wrappers(sql, params, many=False, executor=self._execute)
  File "D:\Program Files\Python36\lib\site-packages\django\db\backends\utils.py", line 77, in _execute_with_wrappers
    return executor(sql, params, many, context)
  File "D:\Program Files\Python36\lib\site-packages\django\db\backends\utils.py", line 85, in _execute
    return self.cursor.execute(sql, params)
  File "D:\Program Files\Python36\lib\site-packages\django\db\utils.py", line 89, in __exit__
    raise dj_exc_value.with_traceback(traceback) from exc_value
  File "D:\Program Files\Python36\lib\site-packages\django\db\backends\utils.py", line 85, in _execute
    return self.cursor.execute(sql, params)
  File "D:\Program Files\Python36\lib\site-packages\django\db\backends\sqlite3\base.py", line 303, in execute
    return Database.Cursor.execute(self, query, params)
django.db.utils.IntegrityError: FOREIGN KEY constraint failed

0927_23:14:55 Traceback (most recent call last):
  File "D:\Program Files\Python36\lib\site-packages\django\db\backends\utils.py", line 85, in _execute
    return self.cursor.execute(sql, params)
  File "D:\Program Files\Python36\lib\site-packages\django\db\backends\sqlite3\base.py", line 303, in execute
    return Database.Cursor.execute(self, query, params)
sqlite3.IntegrityError: FOREIGN KEY constraint failed

The above exception was the direct cause of the following exception:

Traceback (most recent call last):
  File "C:\Users\Think\Desktop\入口\自动化测试\restapi-teach\backend\services\datamodel\common\models.py", line 206, in add
    teacher.courses.add(*courseidList)
  File "D:\Program Files\Python36\lib\site-packages\django\db\models\fields\related_descriptors.py", line 898, in add
    self._add_items(self.source_field_name, self.target_field_name, *objs)
  File "D:\Program Files\Python36\lib\site-packages\django\db\models\fields\related_descriptors.py", line 1065, in _add_items
    for obj_id in new_ids
  File "D:\Program Files\Python36\lib\site-packages\django\db\models\query.py", line 466, in bulk_create
    ids = self._batched_insert(objs_without_pk, fields, batch_size)
  File "D:\Program Files\Python36\lib\site-packages\django\db\models\query.py", line 1148, in _batched_insert
    self._insert(item, fields=fields, using=self.db)
  File "D:\Program Files\Python36\lib\site-packages\django\db\models\query.py", line 1125, in _insert
    return query.get_compiler(using=using).execute_sql(return_id)
  File "D:\Program Files\Python36\lib\site-packages\django\db\models\sql\compiler.py", line 1284, in execute_sql
    cursor.execute(sql, params)
  File "D:\Program Files\Python36\lib\site-packages\django\db\backends\utils.py", line 100, in execute
    return super().execute(sql, params)
  File "D:\Program Files\Python36\lib\site-packages\django\db\backends\utils.py", line 68, in execute
    return self._execute_with_wrappers(sql, params, many=False, executor=self._execute)
  File "D:\Program Files\Python36\lib\site-packages\django\db\backends\utils.py", line 77, in _execute_with_wrappers
    return executor(sql, params, many, context)
  File "D:\Program Files\Python36\lib\site-packages\django\db\backends\utils.py", line 85, in _execute
    return self.cursor.execute(sql, params)
  File "D:\Program Files\Python36\lib\site-packages\django\db\utils.py", line 89, in __exit__
    raise dj_exc_value.with_traceback(traceback) from exc_value
  File "D:\Program Files\Python36\lib\site-packages\django\db\backends\utils.py", line 85, in _execute
    return self.cursor.execute(sql, params)
  File "D:\Program Files\Python36\lib\site-packages\django\db\backends\sqlite3\base.py", line 303, in execute
    return Database.Cursor.execute(self, query, params)
django.db.utils.IntegrityError: FOREIGN KEY constraint failed

0927_23:15:22 Traceback (most recent call last):
  File "D:\Program Files\Python36\lib\site-packages\django\db\backends\utils.py", line 85, in _execute
    return self.cursor.execute(sql, params)
  File "D:\Program Files\Python36\lib\site-packages\django\db\backends\sqlite3\base.py", line 303, in execute
    return Database.Cursor.execute(self, query, params)
sqlite3.IntegrityError: FOREIGN KEY constraint failed

The above exception was the direct cause of the following exception:

Traceback (most recent call last):
  File "C:\Users\Think\Desktop\入口\自动化测试\restapi-teach\backend\services\datamodel\common\models.py", line 206, in add
    teacher.courses.add(*courseidList)
  File "D:\Program Files\Python36\lib\site-packages\django\db\models\fields\related_descriptors.py", line 898, in add
    self._add_items(self.source_field_name, self.target_field_name, *objs)
  File "D:\Program Files\Python36\lib\site-packages\django\db\models\fields\related_descriptors.py", line 1065, in _add_items
    for obj_id in new_ids
  File "D:\Program Files\Python36\lib\site-packages\django\db\models\query.py", line 466, in bulk_create
    ids = self._batched_insert(objs_without_pk, fields, batch_size)
  File "D:\Program Files\Python36\lib\site-packages\django\db\models\query.py", line 1148, in _batched_insert
    self._insert(item, fields=fields, using=self.db)
  File "D:\Program Files\Python36\lib\site-packages\django\db\models\query.py", line 1125, in _insert
    return query.get_compiler(using=using).execute_sql(return_id)
  File "D:\Program Files\Python36\lib\site-packages\django\db\models\sql\compiler.py", line 1284, in execute_sql
    cursor.execute(sql, params)
  File "D:\Program Files\Python36\lib\site-packages\django\db\backends\utils.py", line 100, in execute
    return super().execute(sql, params)
  File "D:\Program Files\Python36\lib\site-packages\django\db\backends\utils.py", line 68, in execute
    return self._execute_with_wrappers(sql, params, many=False, executor=self._execute)
  File "D:\Program Files\Python36\lib\site-packages\django\db\backends\utils.py", line 77, in _execute_with_wrappers
    return executor(sql, params, many, context)
  File "D:\Program Files\Python36\lib\site-packages\django\db\backends\utils.py", line 85, in _execute
    return self.cursor.execute(sql, params)
  File "D:\Program Files\Python36\lib\site-packages\django\db\utils.py", line 89, in __exit__
    raise dj_exc_value.with_traceback(traceback) from exc_value
  File "D:\Program Files\Python36\lib\site-packages\django\db\backends\utils.py", line 85, in _execute
    return self.cursor.execute(sql, params)
  File "D:\Program Files\Python36\lib\site-packages\django\db\backends\sqlite3\base.py", line 303, in execute
    return Database.Cursor.execute(self, query, params)
django.db.utils.IntegrityError: FOREIGN KEY constraint failed

0929_09:18:18 Traceback (most recent call last):
  File "D:\Program Files\Python36\lib\site-packages\django\db\backends\utils.py", line 85, in _execute
    return self.cursor.execute(sql, params)
  File "D:\Program Files\Python36\lib\site-packages\django\db\backends\sqlite3\base.py", line 303, in execute
    return Database.Cursor.execute(self, query, params)
sqlite3.IntegrityError: FOREIGN KEY constraint failed

The above exception was the direct cause of the following exception:

Traceback (most recent call last):
  File "C:\Users\Think\Desktop\入口\自动化测试\restapi-teach\backend\services\datamodel\common\models.py", line 206, in add
    teacher.courses.add(*courseidList)
  File "D:\Program Files\Python36\lib\site-packages\django\db\models\fields\related_descriptors.py", line 898, in add
    self._add_items(self.source_field_name, self.target_field_name, *objs)
  File "D:\Program Files\Python36\lib\site-packages\django\db\models\fields\related_descriptors.py", line 1065, in _add_items
    for obj_id in new_ids
  File "D:\Program Files\Python36\lib\site-packages\django\db\models\query.py", line 466, in bulk_create
    ids = self._batched_insert(objs_without_pk, fields, batch_size)
  File "D:\Program Files\Python36\lib\site-packages\django\db\models\query.py", line 1148, in _batched_insert
    self._insert(item, fields=fields, using=self.db)
  File "D:\Program Files\Python36\lib\site-packages\django\db\models\query.py", line 1125, in _insert
    return query.get_compiler(using=using).execute_sql(return_id)
  File "D:\Program Files\Python36\lib\site-packages\django\db\models\sql\compiler.py", line 1284, in execute_sql
    cursor.execute(sql, params)
  File "D:\Program Files\Python36\lib\site-packages\django\db\backends\utils.py", line 100, in execute
    return super().execute(sql, params)
  File "D:\Program Files\Python36\lib\site-packages\django\db\backends\utils.py", line 68, in execute
    return self._execute_with_wrappers(sql, params, many=False, executor=self._execute)
  File "D:\Program Files\Python36\lib\site-packages\django\db\backends\utils.py", line 77, in _execute_with_wrappers
    return executor(sql, params, many, context)
  File "D:\Program Files\Python36\lib\site-packages\django\db\backends\utils.py", line 85, in _execute
    return self.cursor.execute(sql, params)
  File "D:\Program Files\Python36\lib\site-packages\django\db\utils.py", line 89, in __exit__
    raise dj_exc_value.with_traceback(traceback) from exc_value
  File "D:\Program Files\Python36\lib\site-packages\django\db\backends\utils.py", line 85, in _execute
    return self.cursor.execute(sql, params)
  File "D:\Program Files\Python36\lib\site-packages\django\db\backends\sqlite3\base.py", line 303, in execute
    return Database.Cursor.execute(self, query, params)
django.db.utils.IntegrityError: FOREIGN KEY constraint failed

0929_09:18:52 Traceback (most recent call last):
  File "D:\Program Files\Python36\lib\site-packages\django\db\backends\utils.py", line 85, in _execute
    return self.cursor.execute(sql, params)
  File "D:\Program Files\Python36\lib\site-packages\django\db\backends\sqlite3\base.py", line 303, in execute
    return Database.Cursor.execute(self, query, params)
sqlite3.IntegrityError: FOREIGN KEY constraint failed

The above exception was the direct cause of the following exception:

Traceback (most recent call last):
  File "C:\Users\Think\Desktop\入口\自动化测试\restapi-teach\backend\services\datamodel\common\models.py", line 206, in add
    teacher.courses.add(*courseidList)
  File "D:\Program Files\Python36\lib\site-packages\django\db\models\fields\related_descriptors.py", line 898, in add
    self._add_items(self.source_field_name, self.target_field_name, *objs)
  File "D:\Program Files\Python36\lib\site-packages\django\db\models\fields\related_descriptors.py", line 1065, in _add_items
    for obj_id in new_ids
  File "D:\Program Files\Python36\lib\site-packages\django\db\models\query.py", line 466, in bulk_create
    ids = self._batched_insert(objs_without_pk, fields, batch_size)
  File "D:\Program Files\Python36\lib\site-packages\django\db\models\query.py", line 1148, in _batched_insert
    self._insert(item, fields=fields, using=self.db)
  File "D:\Program Files\Python36\lib\site-packages\django\db\models\query.py", line 1125, in _insert
    return query.get_compiler(using=using).execute_sql(return_id)
  File "D:\Program Files\Python36\lib\site-packages\django\db\models\sql\compiler.py", line 1284, in execute_sql
    cursor.execute(sql, params)
  File "D:\Program Files\Python36\lib\site-packages\django\db\backends\utils.py", line 100, in execute
    return super().execute(sql, params)
  File "D:\Program Files\Python36\lib\site-packages\django\db\backends\utils.py", line 68, in execute
    return self._execute_with_wrappers(sql, params, many=False, executor=self._execute)
  File "D:\Program Files\Python36\lib\site-packages\django\db\backends\utils.py", line 77, in _execute_with_wrappers
    return executor(sql, params, many, context)
  File "D:\Program Files\Python36\lib\site-packages\django\db\backends\utils.py", line 85, in _execute
    return self.cursor.execute(sql, params)
  File "D:\Program Files\Python36\lib\site-packages\django\db\utils.py", line 89, in __exit__
    raise dj_exc_value.with_traceback(traceback) from exc_value
  File "D:\Program Files\Python36\lib\site-packages\django\db\backends\utils.py", line 85, in _execute
    return self.cursor.execute(sql, params)
  File "D:\Program Files\Python36\lib\site-packages\django\db\backends\sqlite3\base.py", line 303, in execute
    return Database.Cursor.execute(self, query, params)
django.db.utils.IntegrityError: FOREIGN KEY constraint failed

0929_09:18:59 Traceback (most recent call last):
  File "D:\Program Files\Python36\lib\site-packages\django\db\backends\utils.py", line 85, in _execute
    return self.cursor.execute(sql, params)
  File "D:\Program Files\Python36\lib\site-packages\django\db\backends\sqlite3\base.py", line 303, in execute
    return Database.Cursor.execute(self, query, params)
sqlite3.IntegrityError: FOREIGN KEY constraint failed

The above exception was the direct cause of the following exception:

Traceback (most recent call last):
  File "C:\Users\Think\Desktop\入口\自动化测试\restapi-teach\backend\services\datamodel\common\models.py", line 206, in add
    teacher.courses.add(*courseidList)
  File "D:\Program Files\Python36\lib\site-packages\django\db\models\fields\related_descriptors.py", line 898, in add
    self._add_items(self.source_field_name, self.target_field_name, *objs)
  File "D:\Program Files\Python36\lib\site-packages\django\db\models\fields\related_descriptors.py", line 1065, in _add_items
    for obj_id in new_ids
  File "D:\Program Files\Python36\lib\site-packages\django\db\models\query.py", line 466, in bulk_create
    ids = self._batched_insert(objs_without_pk, fields, batch_size)
  File "D:\Program Files\Python36\lib\site-packages\django\db\models\query.py", line 1148, in _batched_insert
    self._insert(item, fields=fields, using=self.db)
  File "D:\Program Files\Python36\lib\site-packages\django\db\models\query.py", line 1125, in _insert
    return query.get_compiler(using=using).execute_sql(return_id)
  File "D:\Program Files\Python36\lib\site-packages\django\db\models\sql\compiler.py", line 1284, in execute_sql
    cursor.execute(sql, params)
  File "D:\Program Files\Python36\lib\site-packages\django\db\backends\utils.py", line 100, in execute
    return super().execute(sql, params)
  File "D:\Program Files\Python36\lib\site-packages\django\db\backends\utils.py", line 68, in execute
    return self._execute_with_wrappers(sql, params, many=False, executor=self._execute)
  File "D:\Program Files\Python36\lib\site-packages\django\db\backends\utils.py", line 77, in _execute_with_wrappers
    return executor(sql, params, many, context)
  File "D:\Program Files\Python36\lib\site-packages\django\db\backends\utils.py", line 85, in _execute
    return self.cursor.execute(sql, params)
  File "D:\Program Files\Python36\lib\site-packages\django\db\utils.py", line 89, in __exit__
    raise dj_exc_value.with_traceback(traceback) from exc_value
  File "D:\Program Files\Python36\lib\site-packages\django\db\backends\utils.py", line 85, in _execute
    return self.cursor.execute(sql, params)
  File "D:\Program Files\Python36\lib\site-packages\django\db\backends\sqlite3\base.py", line 303, in execute
    return Database.Cursor.execute(self, query, params)
django.db.utils.IntegrityError: FOREIGN KEY constraint failed

0929_09:27:17 Traceback (most recent call last):
  File "D:\Program Files\Python36\lib\site-packages\django\db\backends\utils.py", line 85, in _execute
    return self.cursor.execute(sql, params)
  File "D:\Program Files\Python36\lib\site-packages\django\db\backends\sqlite3\base.py", line 303, in execute
    return Database.Cursor.execute(self, query, params)
sqlite3.IntegrityError: FOREIGN KEY constraint failed

The above exception was the direct cause of the following exception:

Traceback (most recent call last):
  File "C:\Users\Think\Desktop\入口\自动化测试\restapi-teach\backend\services\datamodel\common\models.py", line 206, in add
    teacher.courses.add(*courseidList)
  File "D:\Program Files\Python36\lib\site-packages\django\db\models\fields\related_descriptors.py", line 898, in add
    self._add_items(self.source_field_name, self.target_field_name, *objs)
  File "D:\Program Files\Python36\lib\site-packages\django\db\models\fields\related_descriptors.py", line 1065, in _add_items
    for obj_id in new_ids
  File "D:\Program Files\Python36\lib\site-packages\django\db\models\query.py", line 466, in bulk_create
    ids = self._batched_insert(objs_without_pk, fields, batch_size)
  File "D:\Program Files\Python36\lib\site-packages\django\db\models\query.py", line 1148, in _batched_insert
    self._insert(item, fields=fields, using=self.db)
  File "D:\Program Files\Python36\lib\site-packages\django\db\models\query.py", line 1125, in _insert
    return query.get_compiler(using=using).execute_sql(return_id)
  File "D:\Program Files\Python36\lib\site-packages\django\db\models\sql\compiler.py", line 1284, in execute_sql
    cursor.execute(sql, params)
  File "D:\Program Files\Python36\lib\site-packages\django\db\backends\utils.py", line 100, in execute
    return super().execute(sql, params)
  File "D:\Program Files\Python36\lib\site-packages\django\db\backends\utils.py", line 68, in execute
    return self._execute_with_wrappers(sql, params, many=False, executor=self._execute)
  File "D:\Program Files\Python36\lib\site-packages\django\db\backends\utils.py", line 77, in _execute_with_wrappers
    return executor(sql, params, many, context)
  File "D:\Program Files\Python36\lib\site-packages\django\db\backends\utils.py", line 85, in _execute
    return self.cursor.execute(sql, params)
  File "D:\Program Files\Python36\lib\site-packages\django\db\utils.py", line 89, in __exit__
    raise dj_exc_value.with_traceback(traceback) from exc_value
  File "D:\Program Files\Python36\lib\site-packages\django\db\backends\utils.py", line 85, in _execute
    return self.cursor.execute(sql, params)
  File "D:\Program Files\Python36\lib\site-packages\django\db\backends\sqlite3\base.py", line 303, in execute
    return Database.Cursor.execute(self, query, params)
django.db.utils.IntegrityError: FOREIGN KEY constraint failed

1015_21:18:51 Traceback (most recent call last):
  File "D:\Program Files\Python36\lib\site-packages\django\db\backends\utils.py", line 85, in _execute
    return self.cursor.execute(sql, params)
  File "D:\Program Files\Python36\lib\site-packages\django\db\backends\sqlite3\base.py", line 303, in execute
    return Database.Cursor.execute(self, query, params)
sqlite3.IntegrityError: FOREIGN KEY constraint failed

The above exception was the direct cause of the following exception:

Traceback (most recent call last):
  File "C:\Users\Think\Desktop\入口\自动化测试\restapi-teach\backend\services\datamodel\common\models.py", line 206, in add
    teacher.courses.add(*courseidList)
  File "D:\Program Files\Python36\lib\site-packages\django\db\models\fields\related_descriptors.py", line 898, in add
    self._add_items(self.source_field_name, self.target_field_name, *objs)
  File "D:\Program Files\Python36\lib\site-packages\django\db\models\fields\related_descriptors.py", line 1065, in _add_items
    for obj_id in new_ids
  File "D:\Program Files\Python36\lib\site-packages\django\db\models\query.py", line 466, in bulk_create
    ids = self._batched_insert(objs_without_pk, fields, batch_size)
  File "D:\Program Files\Python36\lib\site-packages\django\db\models\query.py", line 1148, in _batched_insert
    self._insert(item, fields=fields, using=self.db)
  File "D:\Program Files\Python36\lib\site-packages\django\db\models\query.py", line 1125, in _insert
    return query.get_compiler(using=using).execute_sql(return_id)
  File "D:\Program Files\Python36\lib\site-packages\django\db\models\sql\compiler.py", line 1284, in execute_sql
    cursor.execute(sql, params)
  File "D:\Program Files\Python36\lib\site-packages\django\db\backends\utils.py", line 100, in execute
    return super().execute(sql, params)
  File "D:\Program Files\Python36\lib\site-packages\django\db\backends\utils.py", line 68, in execute
    return self._execute_with_wrappers(sql, params, many=False, executor=self._execute)
  File "D:\Program Files\Python36\lib\site-packages\django\db\backends\utils.py", line 77, in _execute_with_wrappers
    return executor(sql, params, many, context)
  File "D:\Program Files\Python36\lib\site-packages\django\db\backends\utils.py", line 85, in _execute
    return self.cursor.execute(sql, params)
  File "D:\Program Files\Python36\lib\site-packages\django\db\utils.py", line 89, in __exit__
    raise dj_exc_value.with_traceback(traceback) from exc_value
  File "D:\Program Files\Python36\lib\site-packages\django\db\backends\utils.py", line 85, in _execute
    return self.cursor.execute(sql, params)
  File "D:\Program Files\Python36\lib\site-packages\django\db\backends\sqlite3\base.py", line 303, in execute
    return Database.Cursor.execute(self, query, params)
django.db.utils.IntegrityError: FOREIGN KEY constraint failed

1015_21:53:03 Traceback (most recent call last):
  File "C:\Users\Think\Desktop\入口\自动化测试\restapi-teach\backend\services\datamodel\common\models.py", line 252, in modify
    teacher.courses.add(one['id'])
TypeError: string indices must be integers

1015_21:56:08 Traceback (most recent call last):
  File "C:\Users\Think\Desktop\入口\自动化测试\restapi-teach\backend\services\datamodel\common\models.py", line 252, in modify
    teacher.courses.add(one['id'])
TypeError: string indices must be integers

1015_21:56:42 Traceback (most recent call last):
  File "C:\Users\Think\Desktop\入口\自动化测试\restapi-teach\backend\services\datamodel\common\models.py", line 252, in modify
    teacher.courses.add(one['id'])
TypeError: string indices must be integers

0406_18:08:47 Traceback (most recent call last):
  File "/Users/wgz/Desktop/restapi-teach/backend/services/datamodel/common/models.py", line 280, in add
    teacher.save()
  File "/Library/Frameworks/Python.framework/Versions/3.7/lib/python3.7/site-packages/django/db/models/base.py", line 729, in save
    force_update=force_update, update_fields=update_fields)
  File "/Library/Frameworks/Python.framework/Versions/3.7/lib/python3.7/site-packages/django/db/models/base.py", line 759, in save_base
    updated = self._save_table(raw, cls, force_insert, force_update, using, update_fields)
  File "/Library/Frameworks/Python.framework/Versions/3.7/lib/python3.7/site-packages/django/db/models/base.py", line 842, in _save_table
    result = self._do_insert(cls._base_manager, using, fields, update_pk, raw)
  File "/Library/Frameworks/Python.framework/Versions/3.7/lib/python3.7/site-packages/django/db/models/base.py", line 880, in _do_insert
    using=using, raw=raw)
  File "/Library/Frameworks/Python.framework/Versions/3.7/lib/python3.7/site-packages/django/db/models/manager.py", line 82, in manager_method
    return getattr(self.get_queryset(), name)(*args, **kwargs)
  File "/Library/Frameworks/Python.framework/Versions/3.7/lib/python3.7/site-packages/django/db/models/query.py", line 1125, in _insert
    return query.get_compiler(using=using).execute_sql(return_id)
  File "/Library/Frameworks/Python.framework/Versions/3.7/lib/python3.7/site-packages/django/db/models/sql/compiler.py", line 1283, in execute_sql
    for sql, params in self.as_sql():
  File "/Library/Frameworks/Python.framework/Versions/3.7/lib/python3.7/site-packages/django/db/models/sql/compiler.py", line 1236, in as_sql
    for obj in self.query.objs
  File "/Library/Frameworks/Python.framework/Versions/3.7/lib/python3.7/site-packages/django/db/models/sql/compiler.py", line 1236, in <listcomp>
    for obj in self.query.objs
  File "/Library/Frameworks/Python.framework/Versions/3.7/lib/python3.7/site-packages/django/db/models/sql/compiler.py", line 1235, in <listcomp>
    [self.prepare_value(field, self.pre_save_val(field, obj)) for field in fields]
  File "/Library/Frameworks/Python.framework/Versions/3.7/lib/python3.7/site-packages/django/db/models/sql/compiler.py", line 1175, in prepare_value
    value = field.get_db_prep_save(value, connection=self.connection)
  File "/Library/Frameworks/Python.framework/Versions/3.7/lib/python3.7/site-packages/django/db/models/fields/__init__.py", line 767, in get_db_prep_save
    return self.get_db_prep_value(value, connection=connection, prepared=False)
  File "/Library/Frameworks/Python.framework/Versions/3.7/lib/python3.7/site-packages/django/db/models/fields/__init__.py", line 762, in get_db_prep_value
    value = self.get_prep_value(value)
  File "/Library/Frameworks/Python.framework/Versions/3.7/lib/python3.7/site-packages/django/db/models/fields/__init__.py", line 1826, in get_prep_value
    return int(value)
ValueError: invalid literal for int() with base 10: '1d'

0406_18:08:52 Traceback (most recent call last):
  File "/Users/wgz/Desktop/restapi-teach/backend/services/datamodel/common/models.py", line 280, in add
    teacher.save()
  File "/Library/Frameworks/Python.framework/Versions/3.7/lib/python3.7/site-packages/django/db/models/base.py", line 729, in save
    force_update=force_update, update_fields=update_fields)
  File "/Library/Frameworks/Python.framework/Versions/3.7/lib/python3.7/site-packages/django/db/models/base.py", line 759, in save_base
    updated = self._save_table(raw, cls, force_insert, force_update, using, update_fields)
  File "/Library/Frameworks/Python.framework/Versions/3.7/lib/python3.7/site-packages/django/db/models/base.py", line 842, in _save_table
    result = self._do_insert(cls._base_manager, using, fields, update_pk, raw)
  File "/Library/Frameworks/Python.framework/Versions/3.7/lib/python3.7/site-packages/django/db/models/base.py", line 880, in _do_insert
    using=using, raw=raw)
  File "/Library/Frameworks/Python.framework/Versions/3.7/lib/python3.7/site-packages/django/db/models/manager.py", line 82, in manager_method
    return getattr(self.get_queryset(), name)(*args, **kwargs)
  File "/Library/Frameworks/Python.framework/Versions/3.7/lib/python3.7/site-packages/django/db/models/query.py", line 1125, in _insert
    return query.get_compiler(using=using).execute_sql(return_id)
  File "/Library/Frameworks/Python.framework/Versions/3.7/lib/python3.7/site-packages/django/db/models/sql/compiler.py", line 1283, in execute_sql
    for sql, params in self.as_sql():
  File "/Library/Frameworks/Python.framework/Versions/3.7/lib/python3.7/site-packages/django/db/models/sql/compiler.py", line 1236, in as_sql
    for obj in self.query.objs
  File "/Library/Frameworks/Python.framework/Versions/3.7/lib/python3.7/site-packages/django/db/models/sql/compiler.py", line 1236, in <listcomp>
    for obj in self.query.objs
  File "/Library/Frameworks/Python.framework/Versions/3.7/lib/python3.7/site-packages/django/db/models/sql/compiler.py", line 1235, in <listcomp>
    [self.prepare_value(field, self.pre_save_val(field, obj)) for field in fields]
  File "/Library/Frameworks/Python.framework/Versions/3.7/lib/python3.7/site-packages/django/db/models/sql/compiler.py", line 1175, in prepare_value
    value = field.get_db_prep_save(value, connection=self.connection)
  File "/Library/Frameworks/Python.framework/Versions/3.7/lib/python3.7/site-packages/django/db/models/fields/__init__.py", line 767, in get_db_prep_save
    return self.get_db_prep_value(value, connection=connection, prepared=False)
  File "/Library/Frameworks/Python.framework/Versions/3.7/lib/python3.7/site-packages/django/db/models/fields/__init__.py", line 762, in get_db_prep_value
    value = self.get_prep_value(value)
  File "/Library/Frameworks/Python.framework/Versions/3.7/lib/python3.7/site-packages/django/db/models/fields/__init__.py", line 1826, in get_prep_value
    return int(value)
ValueError: invalid literal for int() with base 10: '1dfsf'

0406_18:09:01 Traceback (most recent call last):
  File "/Users/wgz/Desktop/restapi-teach/backend/services/datamodel/common/models.py", line 280, in add
    teacher.save()
  File "/Library/Frameworks/Python.framework/Versions/3.7/lib/python3.7/site-packages/django/db/models/base.py", line 729, in save
    force_update=force_update, update_fields=update_fields)
  File "/Library/Frameworks/Python.framework/Versions/3.7/lib/python3.7/site-packages/django/db/models/base.py", line 759, in save_base
    updated = self._save_table(raw, cls, force_insert, force_update, using, update_fields)
  File "/Library/Frameworks/Python.framework/Versions/3.7/lib/python3.7/site-packages/django/db/models/base.py", line 842, in _save_table
    result = self._do_insert(cls._base_manager, using, fields, update_pk, raw)
  File "/Library/Frameworks/Python.framework/Versions/3.7/lib/python3.7/site-packages/django/db/models/base.py", line 880, in _do_insert
    using=using, raw=raw)
  File "/Library/Frameworks/Python.framework/Versions/3.7/lib/python3.7/site-packages/django/db/models/manager.py", line 82, in manager_method
    return getattr(self.get_queryset(), name)(*args, **kwargs)
  File "/Library/Frameworks/Python.framework/Versions/3.7/lib/python3.7/site-packages/django/db/models/query.py", line 1125, in _insert
    return query.get_compiler(using=using).execute_sql(return_id)
  File "/Library/Frameworks/Python.framework/Versions/3.7/lib/python3.7/site-packages/django/db/models/sql/compiler.py", line 1283, in execute_sql
    for sql, params in self.as_sql():
  File "/Library/Frameworks/Python.framework/Versions/3.7/lib/python3.7/site-packages/django/db/models/sql/compiler.py", line 1236, in as_sql
    for obj in self.query.objs
  File "/Library/Frameworks/Python.framework/Versions/3.7/lib/python3.7/site-packages/django/db/models/sql/compiler.py", line 1236, in <listcomp>
    for obj in self.query.objs
  File "/Library/Frameworks/Python.framework/Versions/3.7/lib/python3.7/site-packages/django/db/models/sql/compiler.py", line 1235, in <listcomp>
    [self.prepare_value(field, self.pre_save_val(field, obj)) for field in fields]
  File "/Library/Frameworks/Python.framework/Versions/3.7/lib/python3.7/site-packages/django/db/models/sql/compiler.py", line 1175, in prepare_value
    value = field.get_db_prep_save(value, connection=self.connection)
  File "/Library/Frameworks/Python.framework/Versions/3.7/lib/python3.7/site-packages/django/db/models/fields/__init__.py", line 767, in get_db_prep_save
    return self.get_db_prep_value(value, connection=connection, prepared=False)
  File "/Library/Frameworks/Python.framework/Versions/3.7/lib/python3.7/site-packages/django/db/models/fields/__init__.py", line 762, in get_db_prep_value
    value = self.get_prep_value(value)
  File "/Library/Frameworks/Python.framework/Versions/3.7/lib/python3.7/site-packages/django/db/models/fields/__init__.py", line 1826, in get_prep_value
    return int(value)
ValueError: invalid literal for int() with base 10: '1dfsf'

0406_18:09:18 Traceback (most recent call last):
  File "/Users/wgz/Desktop/restapi-teach/backend/services/datamodel/common/models.py", line 280, in add
    teacher.save()
  File "/Library/Frameworks/Python.framework/Versions/3.7/lib/python3.7/site-packages/django/db/models/base.py", line 729, in save
    force_update=force_update, update_fields=update_fields)
  File "/Library/Frameworks/Python.framework/Versions/3.7/lib/python3.7/site-packages/django/db/models/base.py", line 759, in save_base
    updated = self._save_table(raw, cls, force_insert, force_update, using, update_fields)
  File "/Library/Frameworks/Python.framework/Versions/3.7/lib/python3.7/site-packages/django/db/models/base.py", line 842, in _save_table
    result = self._do_insert(cls._base_manager, using, fields, update_pk, raw)
  File "/Library/Frameworks/Python.framework/Versions/3.7/lib/python3.7/site-packages/django/db/models/base.py", line 880, in _do_insert
    using=using, raw=raw)
  File "/Library/Frameworks/Python.framework/Versions/3.7/lib/python3.7/site-packages/django/db/models/manager.py", line 82, in manager_method
    return getattr(self.get_queryset(), name)(*args, **kwargs)
  File "/Library/Frameworks/Python.framework/Versions/3.7/lib/python3.7/site-packages/django/db/models/query.py", line 1125, in _insert
    return query.get_compiler(using=using).execute_sql(return_id)
  File "/Library/Frameworks/Python.framework/Versions/3.7/lib/python3.7/site-packages/django/db/models/sql/compiler.py", line 1283, in execute_sql
    for sql, params in self.as_sql():
  File "/Library/Frameworks/Python.framework/Versions/3.7/lib/python3.7/site-packages/django/db/models/sql/compiler.py", line 1236, in as_sql
    for obj in self.query.objs
  File "/Library/Frameworks/Python.framework/Versions/3.7/lib/python3.7/site-packages/django/db/models/sql/compiler.py", line 1236, in <listcomp>
    for obj in self.query.objs
  File "/Library/Frameworks/Python.framework/Versions/3.7/lib/python3.7/site-packages/django/db/models/sql/compiler.py", line 1235, in <listcomp>
    [self.prepare_value(field, self.pre_save_val(field, obj)) for field in fields]
  File "/Library/Frameworks/Python.framework/Versions/3.7/lib/python3.7/site-packages/django/db/models/sql/compiler.py", line 1175, in prepare_value
    value = field.get_db_prep_save(value, connection=self.connection)
  File "/Library/Frameworks/Python.framework/Versions/3.7/lib/python3.7/site-packages/django/db/models/fields/__init__.py", line 767, in get_db_prep_save
    return self.get_db_prep_value(value, connection=connection, prepared=False)
  File "/Library/Frameworks/Python.framework/Versions/3.7/lib/python3.7/site-packages/django/db/models/fields/__init__.py", line 762, in get_db_prep_value
    value = self.get_prep_value(value)
  File "/Library/Frameworks/Python.framework/Versions/3.7/lib/python3.7/site-packages/django/db/models/fields/__init__.py", line 1826, in get_prep_value
    return int(value)
ValueError: invalid literal for int() with base 10: 'd1'

0427_20:15:51 Traceback (most recent call last):
  File "/Users/wgz/Desktop/restapi-teach/backend/services/datamodel/common/models.py", line 283, in add
    courseidList = [one['id'] for one in  data['courses']]
  File "/Users/wgz/Desktop/restapi-teach/backend/services/datamodel/common/models.py", line 283, in <listcomp>
    courseidList = [one['id'] for one in  data['courses']]
TypeError: string indices must be integers

0427_20:16:24 Traceback (most recent call last):
  File "/Users/wgz/Desktop/restapi-teach/backend/services/datamodel/common/models.py", line 283, in add
    courseidList = [one['id'] for one in  data['courses']]
  File "/Users/wgz/Desktop/restapi-teach/backend/services/datamodel/common/models.py", line 283, in <listcomp>
    courseidList = [one['id'] for one in  data['courses']]
TypeError: string indices must be integers

0427_20:27:11 Traceback (most recent call last):
  File "/Users/wgz/Desktop/restapi-teach/backend/services/datamodel/common/models.py", line 283, in add
    courseidList = [one['id'] for one in  data['courses']]
  File "/Users/wgz/Desktop/restapi-teach/backend/services/datamodel/common/models.py", line 283, in <listcomp>
    courseidList = [one['id'] for one in  data['courses']]
TypeError: string indices must be integers

0428_13:20:45 Traceback (most recent call last):
  File "/Library/Frameworks/Python.framework/Versions/3.7/lib/python3.7/site-packages/django/db/backends/utils.py", line 85, in _execute
    return self.cursor.execute(sql, params)
  File "/Library/Frameworks/Python.framework/Versions/3.7/lib/python3.7/site-packages/django/db/backends/sqlite3/base.py", line 303, in execute
    return Database.Cursor.execute(self, query, params)
sqlite3.IntegrityError: FOREIGN KEY constraint failed

The above exception was the direct cause of the following exception:

Traceback (most recent call last):
  File "/Users/wgz/Desktop/restapi-teach/backend/services/datamodel/common/models.py", line 284, in add
    teacher.courses.add(*courseidList)
  File "/Library/Frameworks/Python.framework/Versions/3.7/lib/python3.7/site-packages/django/db/models/fields/related_descriptors.py", line 898, in add
    self._add_items(self.source_field_name, self.target_field_name, *objs)
  File "/Library/Frameworks/Python.framework/Versions/3.7/lib/python3.7/site-packages/django/db/models/fields/related_descriptors.py", line 1065, in _add_items
    for obj_id in new_ids
  File "/Library/Frameworks/Python.framework/Versions/3.7/lib/python3.7/site-packages/django/db/models/query.py", line 466, in bulk_create
    ids = self._batched_insert(objs_without_pk, fields, batch_size)
  File "/Library/Frameworks/Python.framework/Versions/3.7/lib/python3.7/site-packages/django/db/models/query.py", line 1148, in _batched_insert
    self._insert(item, fields=fields, using=self.db)
  File "/Library/Frameworks/Python.framework/Versions/3.7/lib/python3.7/site-packages/django/db/models/query.py", line 1125, in _insert
    return query.get_compiler(using=using).execute_sql(return_id)
  File "/Library/Frameworks/Python.framework/Versions/3.7/lib/python3.7/site-packages/django/db/models/sql/compiler.py", line 1284, in execute_sql
    cursor.execute(sql, params)
  File "/Library/Frameworks/Python.framework/Versions/3.7/lib/python3.7/site-packages/django/db/backends/utils.py", line 100, in execute
    return super().execute(sql, params)
  File "/Library/Frameworks/Python.framework/Versions/3.7/lib/python3.7/site-packages/django/db/backends/utils.py", line 68, in execute
    return self._execute_with_wrappers(sql, params, many=False, executor=self._execute)
  File "/Library/Frameworks/Python.framework/Versions/3.7/lib/python3.7/site-packages/django/db/backends/utils.py", line 77, in _execute_with_wrappers
    return executor(sql, params, many, context)
  File "/Library/Frameworks/Python.framework/Versions/3.7/lib/python3.7/site-packages/django/db/backends/utils.py", line 85, in _execute
    return self.cursor.execute(sql, params)
  File "/Library/Frameworks/Python.framework/Versions/3.7/lib/python3.7/site-packages/django/db/utils.py", line 89, in __exit__
    raise dj_exc_value.with_traceback(traceback) from exc_value
  File "/Library/Frameworks/Python.framework/Versions/3.7/lib/python3.7/site-packages/django/db/backends/utils.py", line 85, in _execute
    return self.cursor.execute(sql, params)
  File "/Library/Frameworks/Python.framework/Versions/3.7/lib/python3.7/site-packages/django/db/backends/sqlite3/base.py", line 303, in execute
    return Database.Cursor.execute(self, query, params)
django.db.utils.IntegrityError: FOREIGN KEY constraint failed

0428_13:21:12 Traceback (most recent call last):
  File "/Library/Frameworks/Python.framework/Versions/3.7/lib/python3.7/site-packages/django/db/backends/utils.py", line 85, in _execute
    return self.cursor.execute(sql, params)
  File "/Library/Frameworks/Python.framework/Versions/3.7/lib/python3.7/site-packages/django/db/backends/sqlite3/base.py", line 303, in execute
    return Database.Cursor.execute(self, query, params)
sqlite3.IntegrityError: FOREIGN KEY constraint failed

The above exception was the direct cause of the following exception:

Traceback (most recent call last):
  File "/Users/wgz/Desktop/restapi-teach/backend/services/datamodel/common/models.py", line 284, in add
    teacher.courses.add(*courseidList)
  File "/Library/Frameworks/Python.framework/Versions/3.7/lib/python3.7/site-packages/django/db/models/fields/related_descriptors.py", line 898, in add
    self._add_items(self.source_field_name, self.target_field_name, *objs)
  File "/Library/Frameworks/Python.framework/Versions/3.7/lib/python3.7/site-packages/django/db/models/fields/related_descriptors.py", line 1065, in _add_items
    for obj_id in new_ids
  File "/Library/Frameworks/Python.framework/Versions/3.7/lib/python3.7/site-packages/django/db/models/query.py", line 466, in bulk_create
    ids = self._batched_insert(objs_without_pk, fields, batch_size)
  File "/Library/Frameworks/Python.framework/Versions/3.7/lib/python3.7/site-packages/django/db/models/query.py", line 1148, in _batched_insert
    self._insert(item, fields=fields, using=self.db)
  File "/Library/Frameworks/Python.framework/Versions/3.7/lib/python3.7/site-packages/django/db/models/query.py", line 1125, in _insert
    return query.get_compiler(using=using).execute_sql(return_id)
  File "/Library/Frameworks/Python.framework/Versions/3.7/lib/python3.7/site-packages/django/db/models/sql/compiler.py", line 1284, in execute_sql
    cursor.execute(sql, params)
  File "/Library/Frameworks/Python.framework/Versions/3.7/lib/python3.7/site-packages/django/db/backends/utils.py", line 100, in execute
    return super().execute(sql, params)
  File "/Library/Frameworks/Python.framework/Versions/3.7/lib/python3.7/site-packages/django/db/backends/utils.py", line 68, in execute
    return self._execute_with_wrappers(sql, params, many=False, executor=self._execute)
  File "/Library/Frameworks/Python.framework/Versions/3.7/lib/python3.7/site-packages/django/db/backends/utils.py", line 77, in _execute_with_wrappers
    return executor(sql, params, many, context)
  File "/Library/Frameworks/Python.framework/Versions/3.7/lib/python3.7/site-packages/django/db/backends/utils.py", line 85, in _execute
    return self.cursor.execute(sql, params)
  File "/Library/Frameworks/Python.framework/Versions/3.7/lib/python3.7/site-packages/django/db/utils.py", line 89, in __exit__
    raise dj_exc_value.with_traceback(traceback) from exc_value
  File "/Library/Frameworks/Python.framework/Versions/3.7/lib/python3.7/site-packages/django/db/backends/utils.py", line 85, in _execute
    return self.cursor.execute(sql, params)
  File "/Library/Frameworks/Python.framework/Versions/3.7/lib/python3.7/site-packages/django/db/backends/sqlite3/base.py", line 303, in execute
    return Database.Cursor.execute(self, query, params)
django.db.utils.IntegrityError: FOREIGN KEY constraint failed

0428_13:22:47 Traceback (most recent call last):
  File "/Library/Frameworks/Python.framework/Versions/3.7/lib/python3.7/site-packages/django/db/backends/utils.py", line 85, in _execute
    return self.cursor.execute(sql, params)
  File "/Library/Frameworks/Python.framework/Versions/3.7/lib/python3.7/site-packages/django/db/backends/sqlite3/base.py", line 303, in execute
    return Database.Cursor.execute(self, query, params)
sqlite3.IntegrityError: FOREIGN KEY constraint failed

The above exception was the direct cause of the following exception:

Traceback (most recent call last):
  File "/Users/wgz/Desktop/restapi-teach/backend/services/datamodel/common/models.py", line 284, in add
    teacher.courses.add(*courseidList)
  File "/Library/Frameworks/Python.framework/Versions/3.7/lib/python3.7/site-packages/django/db/models/fields/related_descriptors.py", line 898, in add
    self._add_items(self.source_field_name, self.target_field_name, *objs)
  File "/Library/Frameworks/Python.framework/Versions/3.7/lib/python3.7/site-packages/django/db/models/fields/related_descriptors.py", line 1065, in _add_items
    for obj_id in new_ids
  File "/Library/Frameworks/Python.framework/Versions/3.7/lib/python3.7/site-packages/django/db/models/query.py", line 466, in bulk_create
    ids = self._batched_insert(objs_without_pk, fields, batch_size)
  File "/Library/Frameworks/Python.framework/Versions/3.7/lib/python3.7/site-packages/django/db/models/query.py", line 1148, in _batched_insert
    self._insert(item, fields=fields, using=self.db)
  File "/Library/Frameworks/Python.framework/Versions/3.7/lib/python3.7/site-packages/django/db/models/query.py", line 1125, in _insert
    return query.get_compiler(using=using).execute_sql(return_id)
  File "/Library/Frameworks/Python.framework/Versions/3.7/lib/python3.7/site-packages/django/db/models/sql/compiler.py", line 1284, in execute_sql
    cursor.execute(sql, params)
  File "/Library/Frameworks/Python.framework/Versions/3.7/lib/python3.7/site-packages/django/db/backends/utils.py", line 100, in execute
    return super().execute(sql, params)
  File "/Library/Frameworks/Python.framework/Versions/3.7/lib/python3.7/site-packages/django/db/backends/utils.py", line 68, in execute
    return self._execute_with_wrappers(sql, params, many=False, executor=self._execute)
  File "/Library/Frameworks/Python.framework/Versions/3.7/lib/python3.7/site-packages/django/db/backends/utils.py", line 77, in _execute_with_wrappers
    return executor(sql, params, many, context)
  File "/Library/Frameworks/Python.framework/Versions/3.7/lib/python3.7/site-packages/django/db/backends/utils.py", line 85, in _execute
    return self.cursor.execute(sql, params)
  File "/Library/Frameworks/Python.framework/Versions/3.7/lib/python3.7/site-packages/django/db/utils.py", line 89, in __exit__
    raise dj_exc_value.with_traceback(traceback) from exc_value
  File "/Library/Frameworks/Python.framework/Versions/3.7/lib/python3.7/site-packages/django/db/backends/utils.py", line 85, in _execute
    return self.cursor.execute(sql, params)
  File "/Library/Frameworks/Python.framework/Versions/3.7/lib/python3.7/site-packages/django/db/backends/sqlite3/base.py", line 303, in execute
    return Database.Cursor.execute(self, query, params)
django.db.utils.IntegrityError: FOREIGN KEY constraint failed

